<!-- First (shoulder) element of the arm. Fixed to its parent. -->
    <joint name="base_joint_support" type="fixed">
    <origin rpy="0 0 0" xyz="0 0 0.5"/>
    <parent link="support"/>
    <child link="lwr_base_link"/>
</joint>


<!-- Second segment of the arm. Joint along z-axis -->
<joint name="lwr_0_joint" type="revolute">
    <origin rpy="0 0 0" xyz="0 0 0.445"/>
    <axis xyz="0 0 1"/>
    <limit effort="1000" lower="-3.14159" upper="3.14159" velocity="3.054"/>
    <parent link="lwr_base_link"/>
    <child link="lwr_1_link"/>
</joint>


<!-- Third segment of the arm. Joint along y-axis -->
<joint name="lwr_1_joint" type="revolute">
    <origin rpy="0 0 0" xyz="0.15 0 0.0"/>
    <axis xyz="0 1 0"/>
    <limit effort="1000" lower="-1.65806" upper="2.70526" velocity="3.054"/>
    <parent link="lwr_1_link"/>
    <child link="lwr_2_link"/>
</joint>


<!-- Fourth element of the arm. z-axis -->
<joint name="lwr_2_joint" type="revolute">
    <origin rpy="0 0 0" xyz="0 0 0.7"/>
    <axis xyz="0 1 0"/>
    <limit effort="100" lower="-2.96705972839" upper="2.96705972839" velocity="2.23402144255"/>
    <parent link="lwr_2_link"/>
    <child link="lwr_3_link"/>
</joint>


<!-- Fifth element of the arm. x-axis -->
<joint name="lwr_3_joint" type="revolute">
    <origin rpy="0 0 0" xyz="0 0 0.115"/>
    <axis xyz="1 0 0"/>
    <limit effort="1000" lower="-6.981" upper="6.981" velocity="6.283"/>
    <parent link="lwr_3_link"/>
    <child link="lwr_4_link"/>
</joint>


<!-- Sixth element of the arm. z-axis -->
<joint name="lwr_4_joint" type="revolute">
    <origin rpy="0 0 0" xyz="0.795 0 0"/>
    <axis xyz="0 1 0"/>
    <limit effort="1000" lower="-2.094" upper="2.094" velocity="6.283"/>
    <parent link="lwr_4_link"/>
    <child link="lwr_5_link"/>
</joint>


<!-- Seventh element of the arm. z-axis -->
<joint name="lwr_5_joint" type="revolute">
    <origin rpy="0 0 0" xyz="0.085 0 0"/>
    <axis xyz="1 0 0"/>
    <limit effort="1000" lower="-6.981" upper="6.981" velocity="6.28319"/>
    <parent link="lwr_5_link"/>
    <child link="lwr_6_link"/>
</joint>
